<?xml version="1.0"?>
<robot name="three_dof_arm">

    <link name="base_link">
        <visual>
            <geometry>
                <box size="0.25 0.25 0.25"/>
            </geometry>
            <material name="blue">
                <color rgba="0 0 1 1"/>
            </material>
            <origin xyz="0 0 0.125" rpy="0 0 0"/>
        </visual>
        <collision>
            <geometry>
                <box size="0.25 0.25 0.25"/>
            </geometry>
            <origin xyz="0 0 0.125" rpy="0 0 0"/>
        </collision>
        <inertial>
            <mass value="1.0"/>
            <inertia ixx="0.001" ixy="0.0" ixz="0.0" iyy="0.001" iyz="0.0" izz="0.001"/>
            <origin xyz="0 0 0.125" rpy="0 0 0"/>
        </inertial>
    </link>

    <joint name="joint1" type="revolute">
        <parent link="base_link"/>
        <child link="link1"/>
        <origin xyz="0 0 0.25" rpy="0 0 0"/>
        <axis xyz="0 0 1"/>
        <limit lower="-1.57079" upper="1.57079" effort="10" velocity="1"/>
    </joint>

    <link name="link1">
        <visual>
            <geometry>
                <cylinder length="0.5" radius="0.05"/>
            </geometry>
            <material name="green">
                <color rgba="0 1 0 1"/>
            </material>
            <origin xyz="0 0 0.25" rpy="0 0 0"/>
        </visual>
        <collision>
            <geometry>
                <cylinder length="0.5" radius="0.05"/>
            </geometry>
            <origin xyz="0 0 0.25" rpy="0 0 0"/>
        </collision>
        <inertial>
            <mass value="1.0"/>
            <inertia ixx="0.002" ixy="0.0" ixz="0.0" iyy="0.002" iyz="0.0" izz="0.001"/>
            <origin xyz="0 0 0.25" rpy="0 0 0"/>
        </inertial>
    </link>

    <joint name="joint2" type="revolute">
        <parent link="link1"/>
        <child link="link2"/>
        <origin xyz="0 0 0.5" rpy="0 1.57079 0"/>
        <axis xyz="0 0 1"/>
        <limit lower="-1.57079" upper="1.57079" effort="10" velocity="1"/>
    </joint>

    <link name="link2">
        <visual>
            <geometry>
                <cylinder length="0.5" radius="0.05"/>
            </geometry>
            <origin xyz="-0.25 0 0" rpy="0 -1.57079 0"/>
            <material name="red">
                <color rgba="1 0 0 1"/>
            </material>
        </visual>
        <collision>
            <geometry>
                <cylinder length="0.5" radius="0.05"/>
            </geometry>
            <origin xyz="-0.25 0 0" rpy="0 -1.57079 0"/>
        </collision>
        <inertial>
            <mass value="1.0"/>
            <inertia ixx="0.002" ixy="0.0" ixz="0.0" iyy="0.002" iyz="0.0" izz="0.001"/>
            <origin xyz="-0.25 0 0" rpy="0 -1.57079 0"/>
        </inertial>
    </link>

    <joint name="joint3" type="revolute">
        <parent link="link2"/>
        <child link="link3"/>
        <origin xyz="-0.5 0 0" rpy="0 0 0"/>
        <axis xyz="0 0 1"/>
        <limit lower="-1.57079" upper="1.57079" effort="10" velocity="1"/>
    </joint>

    <link name="link3">
        <visual>
            <geometry>
                <cylinder length="0.5" radius="0.05"/>
            </geometry>
            <material name="yellow">
                <color rgba="1 1 0 1"/>
            </material>
            <origin xyz="-0.25 0 0" rpy="0 -1.57079 0"/>
        </visual>
        <collision>
            <geometry>
                <cylinder length="0.5" radius="0.05"/>
            </geometry>
            <origin xyz="-0.25 0 0" rpy="0 -1.57079 0"/>
        </collision>
        <inertial>
            <mass value="1.0"/>
            <inertia ixx="0.001" ixy="0.0" ixz="0.0" iyy="0.001" iyz="0.0" izz="0.001"/>
            <origin xyz="-0.25 0 0" rpy="0 -1.57079 0"/>
        </inertial>
    </link>

</robot>
